[2023-11-01T11:46:37.053+0000] {taskinstance.py:1157} INFO - Dependencies all met for dep_context=non-requeueable deps ti=<TaskInstance: random_names.streaming_to_kafka manual__2023-11-01T11:46:35.102499+00:00 [queued]>
[2023-11-01T11:46:37.062+0000] {taskinstance.py:1157} INFO - Dependencies all met for dep_context=requeueable deps ti=<TaskInstance: random_names.streaming_to_kafka manual__2023-11-01T11:46:35.102499+00:00 [queued]>
[2023-11-01T11:46:37.062+0000] {taskinstance.py:1359} INFO - Starting attempt 1 of 1
[2023-11-01T11:46:37.081+0000] {taskinstance.py:1380} INFO - Executing <Task(PythonOperator): streaming_to_kafka> on 2023-11-01 11:46:35.102499+00:00
[2023-11-01T11:46:37.086+0000] {standard_task_runner.py:57} INFO - Started process 277 to run task
[2023-11-01T11:46:37.089+0000] {standard_task_runner.py:84} INFO - Running: ['***', 'tasks', 'run', 'random_names', 'streaming_to_kafka', 'manual__2023-11-01T11:46:35.102499+00:00', '--job-id', '76', '--raw', '--subdir', 'DAGS_FOLDER/dag.py', '--cfg-path', '/tmp/tmpwywpf5bz']
[2023-11-01T11:46:37.092+0000] {standard_task_runner.py:85} INFO - Job 76: Subtask streaming_to_kafka
[2023-11-01T11:46:37.138+0000] {task_command.py:415} INFO - Running <TaskInstance: random_names.streaming_to_kafka manual__2023-11-01T11:46:35.102499+00:00 [running]> on host 5158afd90635
[2023-11-01T11:46:37.225+0000] {taskinstance.py:1660} INFO - Exporting env vars: AIRFLOW_CTX_DAG_OWNER='***' AIRFLOW_CTX_DAG_ID='random_names' AIRFLOW_CTX_TASK_ID='streaming_to_kafka' AIRFLOW_CTX_EXECUTION_DATE='2023-11-01T11:46:35.102499+00:00' AIRFLOW_CTX_TRY_NUMBER='1' AIRFLOW_CTX_DAG_RUN_ID='manual__2023-11-01T11:46:35.102499+00:00'
[2023-11-01T11:46:45.233+0000] {taskinstance.py:1935} ERROR - Task failed with exception
Traceback (most recent call last):
  File "/home/airflow/.local/lib/python3.8/site-packages/urllib3/connection.py", line 174, in _new_conn
    conn = connection.create_connection(
  File "/home/airflow/.local/lib/python3.8/site-packages/urllib3/util/connection.py", line 72, in create_connection
    for res in socket.getaddrinfo(host, port, family, socket.SOCK_STREAM):
  File "/usr/local/lib/python3.8/socket.py", line 918, in getaddrinfo
    for res in _socket.getaddrinfo(host, port, family, type, proto, flags):
socket.gaierror: [Errno -3] Temporary failure in name resolution

During handling of the above exception, another exception occurred:

Traceback (most recent call last):
  File "/home/airflow/.local/lib/python3.8/site-packages/urllib3/connectionpool.py", line 714, in urlopen
    httplib_response = self._make_request(
  File "/home/airflow/.local/lib/python3.8/site-packages/urllib3/connectionpool.py", line 403, in _make_request
    self._validate_conn(conn)
  File "/home/airflow/.local/lib/python3.8/site-packages/urllib3/connectionpool.py", line 1053, in _validate_conn
    conn.connect()
  File "/home/airflow/.local/lib/python3.8/site-packages/urllib3/connection.py", line 363, in connect
    self.sock = conn = self._new_conn()
  File "/home/airflow/.local/lib/python3.8/site-packages/urllib3/connection.py", line 186, in _new_conn
    raise NewConnectionError(
urllib3.exceptions.NewConnectionError: <urllib3.connection.HTTPSConnection object at 0x7fc36ca423a0>: Failed to establish a new connection: [Errno -3] Temporary failure in name resolution

During handling of the above exception, another exception occurred:

Traceback (most recent call last):
  File "/home/airflow/.local/lib/python3.8/site-packages/requests/adapters.py", line 486, in send
    resp = conn.urlopen(
  File "/home/airflow/.local/lib/python3.8/site-packages/urllib3/connectionpool.py", line 798, in urlopen
    retries = retries.increment(
  File "/home/airflow/.local/lib/python3.8/site-packages/urllib3/util/retry.py", line 592, in increment
    raise MaxRetryError(_pool, url, error or ResponseError(cause))
urllib3.exceptions.MaxRetryError: HTTPSConnectionPool(host='randomuser.me', port=443): Max retries exceeded with url: /api/ (Caused by NewConnectionError('<urllib3.connection.HTTPSConnection object at 0x7fc36ca423a0>: Failed to establish a new connection: [Errno -3] Temporary failure in name resolution'))

During handling of the above exception, another exception occurred:

Traceback (most recent call last):
  File "/home/airflow/.local/lib/python3.8/site-packages/airflow/operators/python.py", line 192, in execute
    return_value = self.execute_callable()
  File "/home/airflow/.local/lib/python3.8/site-packages/airflow/operators/python.py", line 209, in execute_callable
    return self.python_callable(*self.op_args, **self.op_kwargs)
  File "/opt/airflow/dags/scripts/script.py", line 47, in start_streaming
    data = transform_data(get_API_data())
  File "/opt/airflow/dags/scripts/script.py", line 7, in get_API_data
    response = requests.get('https://randomuser.me/api/')
  File "/home/airflow/.local/lib/python3.8/site-packages/requests/api.py", line 73, in get
    return request("get", url, params=params, **kwargs)
  File "/home/airflow/.local/lib/python3.8/site-packages/requests/api.py", line 59, in request
    return session.request(method=method, url=url, **kwargs)
  File "/home/airflow/.local/lib/python3.8/site-packages/requests/sessions.py", line 589, in request
    resp = self.send(prep, **send_kwargs)
  File "/home/airflow/.local/lib/python3.8/site-packages/requests/sessions.py", line 703, in send
    r = adapter.send(request, **kwargs)
  File "/home/airflow/.local/lib/python3.8/site-packages/requests/adapters.py", line 519, in send
    raise ConnectionError(e, request=request)
requests.exceptions.ConnectionError: HTTPSConnectionPool(host='randomuser.me', port=443): Max retries exceeded with url: /api/ (Caused by NewConnectionError('<urllib3.connection.HTTPSConnection object at 0x7fc36ca423a0>: Failed to establish a new connection: [Errno -3] Temporary failure in name resolution'))
[2023-11-01T11:46:45.270+0000] {taskinstance.py:1398} INFO - Marking task as FAILED. dag_id=random_names, task_id=streaming_to_kafka, execution_date=20231101T114635, start_date=20231101T114637, end_date=20231101T114645
[2023-11-01T11:46:45.389+0000] {standard_task_runner.py:104} ERROR - Failed to execute job 76 for task streaming_to_kafka (HTTPSConnectionPool(host='randomuser.me', port=443): Max retries exceeded with url: /api/ (Caused by NewConnectionError('<urllib3.connection.HTTPSConnection object at 0x7fc36ca423a0>: Failed to establish a new connection: [Errno -3] Temporary failure in name resolution')); 277)
[2023-11-01T11:46:45.401+0000] {local_task_job_runner.py:228} INFO - Task exited with return code 1
[2023-11-01T11:46:45.419+0000] {taskinstance.py:2776} INFO - 0 downstream tasks scheduled from follow-on schedule check
