[2023-10-30T11:42:48.016+0000] {taskinstance.py:1157} INFO - Dependencies all met for dep_context=non-requeueable deps ti=<TaskInstance: random_names.streaming_to_kafka manual__2023-10-30T11:42:36.429836+00:00 [queued]>
[2023-10-30T11:42:48.024+0000] {taskinstance.py:1157} INFO - Dependencies all met for dep_context=requeueable deps ti=<TaskInstance: random_names.streaming_to_kafka manual__2023-10-30T11:42:36.429836+00:00 [queued]>
[2023-10-30T11:42:48.024+0000] {taskinstance.py:1359} INFO - Starting attempt 1 of 1
[2023-10-30T11:42:48.077+0000] {taskinstance.py:1380} INFO - Executing <Task(PythonOperator): streaming_to_kafka> on 2023-10-30 11:42:36.429836+00:00
[2023-10-30T11:42:48.092+0000] {standard_task_runner.py:57} INFO - Started process 221 to run task
[2023-10-30T11:42:48.103+0000] {standard_task_runner.py:84} INFO - Running: ['***', 'tasks', 'run', 'random_names', 'streaming_to_kafka', 'manual__2023-10-30T11:42:36.429836+00:00', '--job-id', '52', '--raw', '--subdir', 'DAGS_FOLDER/dag.py', '--cfg-path', '/tmp/tmp31q6dnaq']
[2023-10-30T11:42:48.109+0000] {standard_task_runner.py:85} INFO - Job 52: Subtask streaming_to_kafka
[2023-10-30T11:42:48.256+0000] {task_command.py:415} INFO - Running <TaskInstance: random_names.streaming_to_kafka manual__2023-10-30T11:42:36.429836+00:00 [running]> on host 92537b78a77f
[2023-10-30T11:42:48.501+0000] {taskinstance.py:1660} INFO - Exporting env vars: AIRFLOW_CTX_DAG_OWNER='***' AIRFLOW_CTX_DAG_ID='random_names' AIRFLOW_CTX_TASK_ID='streaming_to_kafka' AIRFLOW_CTX_EXECUTION_DATE='2023-10-30T11:42:36.429836+00:00' AIRFLOW_CTX_TRY_NUMBER='1' AIRFLOW_CTX_DAG_RUN_ID='manual__2023-10-30T11:42:36.429836+00:00'
[2023-10-30T11:43:13.542+0000] {taskinstance.py:1935} ERROR - Task failed with exception
Traceback (most recent call last):
  File "/home/airflow/.local/lib/python3.8/site-packages/urllib3/connectionpool.py", line 714, in urlopen
    httplib_response = self._make_request(
  File "/home/airflow/.local/lib/python3.8/site-packages/urllib3/connectionpool.py", line 403, in _make_request
    self._validate_conn(conn)
  File "/home/airflow/.local/lib/python3.8/site-packages/urllib3/connectionpool.py", line 1053, in _validate_conn
    conn.connect()
  File "/home/airflow/.local/lib/python3.8/site-packages/urllib3/connection.py", line 419, in connect
    self.sock = ssl_wrap_socket(
  File "/home/airflow/.local/lib/python3.8/site-packages/urllib3/util/ssl_.py", line 449, in ssl_wrap_socket
    ssl_sock = _ssl_wrap_socket_impl(
  File "/home/airflow/.local/lib/python3.8/site-packages/urllib3/util/ssl_.py", line 493, in _ssl_wrap_socket_impl
    return ssl_context.wrap_socket(sock, server_hostname=server_hostname)
  File "/usr/local/lib/python3.8/ssl.py", line 500, in wrap_socket
    return self.sslsocket_class._create(
  File "/usr/local/lib/python3.8/ssl.py", line 1073, in _create
    self.do_handshake()
  File "/usr/local/lib/python3.8/ssl.py", line 1342, in do_handshake
    self._sslobj.do_handshake()
ConnectionResetError: [Errno 104] Connection reset by peer

During handling of the above exception, another exception occurred:

Traceback (most recent call last):
  File "/home/airflow/.local/lib/python3.8/site-packages/requests/adapters.py", line 486, in send
    resp = conn.urlopen(
  File "/home/airflow/.local/lib/python3.8/site-packages/urllib3/connectionpool.py", line 798, in urlopen
    retries = retries.increment(
  File "/home/airflow/.local/lib/python3.8/site-packages/urllib3/util/retry.py", line 550, in increment
    raise six.reraise(type(error), error, _stacktrace)
  File "/home/airflow/.local/lib/python3.8/site-packages/urllib3/packages/six.py", line 769, in reraise
    raise value.with_traceback(tb)
  File "/home/airflow/.local/lib/python3.8/site-packages/urllib3/connectionpool.py", line 714, in urlopen
    httplib_response = self._make_request(
  File "/home/airflow/.local/lib/python3.8/site-packages/urllib3/connectionpool.py", line 403, in _make_request
    self._validate_conn(conn)
  File "/home/airflow/.local/lib/python3.8/site-packages/urllib3/connectionpool.py", line 1053, in _validate_conn
    conn.connect()
  File "/home/airflow/.local/lib/python3.8/site-packages/urllib3/connection.py", line 419, in connect
    self.sock = ssl_wrap_socket(
  File "/home/airflow/.local/lib/python3.8/site-packages/urllib3/util/ssl_.py", line 449, in ssl_wrap_socket
    ssl_sock = _ssl_wrap_socket_impl(
  File "/home/airflow/.local/lib/python3.8/site-packages/urllib3/util/ssl_.py", line 493, in _ssl_wrap_socket_impl
    return ssl_context.wrap_socket(sock, server_hostname=server_hostname)
  File "/usr/local/lib/python3.8/ssl.py", line 500, in wrap_socket
    return self.sslsocket_class._create(
  File "/usr/local/lib/python3.8/ssl.py", line 1073, in _create
    self.do_handshake()
  File "/usr/local/lib/python3.8/ssl.py", line 1342, in do_handshake
    self._sslobj.do_handshake()
urllib3.exceptions.ProtocolError: ('Connection aborted.', ConnectionResetError(104, 'Connection reset by peer'))

During handling of the above exception, another exception occurred:

Traceback (most recent call last):
  File "/home/airflow/.local/lib/python3.8/site-packages/airflow/operators/python.py", line 192, in execute
    return_value = self.execute_callable()
  File "/home/airflow/.local/lib/python3.8/site-packages/airflow/operators/python.py", line 209, in execute_callable
    return self.python_callable(*self.op_args, **self.op_kwargs)
  File "/opt/airflow/dags/scripts/script.py", line 47, in start_streaming
    data = transform_data(get_API_data())
  File "/opt/airflow/dags/scripts/script.py", line 7, in get_API_data
    response = requests.get('https://randomuser.me/api/')
  File "/home/airflow/.local/lib/python3.8/site-packages/requests/api.py", line 73, in get
    return request("get", url, params=params, **kwargs)
  File "/home/airflow/.local/lib/python3.8/site-packages/requests/api.py", line 59, in request
    return session.request(method=method, url=url, **kwargs)
  File "/home/airflow/.local/lib/python3.8/site-packages/requests/sessions.py", line 589, in request
    resp = self.send(prep, **send_kwargs)
  File "/home/airflow/.local/lib/python3.8/site-packages/requests/sessions.py", line 703, in send
    r = adapter.send(request, **kwargs)
  File "/home/airflow/.local/lib/python3.8/site-packages/requests/adapters.py", line 501, in send
    raise ConnectionError(err, request=request)
requests.exceptions.ConnectionError: ('Connection aborted.', ConnectionResetError(104, 'Connection reset by peer'))
[2023-10-30T11:43:13.996+0000] {taskinstance.py:1398} INFO - Marking task as FAILED. dag_id=random_names, task_id=streaming_to_kafka, execution_date=20231030T114236, start_date=20231030T114248, end_date=20231030T114313
[2023-10-30T11:43:14.876+0000] {standard_task_runner.py:104} ERROR - Failed to execute job 52 for task streaming_to_kafka (('Connection aborted.', ConnectionResetError(104, 'Connection reset by peer')); 221)
[2023-10-30T11:43:14.908+0000] {local_task_job_runner.py:228} INFO - Task exited with return code 1
[2023-10-30T11:43:14.954+0000] {taskinstance.py:2776} INFO - 0 downstream tasks scheduled from follow-on schedule check
